Workbook
Name AnsA: Lookups!$P$4:$P$7
Name AnsATBL: Lookups!$P$4:$Q$7
Name AnsB: Lookups!$P$10:$P$13
Name AnsBTBL: Lookups!$P$10:$Q$13
Name AnsC: Lookups!$P$16:$P$19
Name AnsCTBL: Lookups!$P$16:$Q$19
Name AnsD: Lookups!$P$22:$P$25
Name AnsDTBL: Lookups!$P$22:$Q$25
Name AnsE: Lookups!$P$28:$P$31
Name AnsETBL: Lookups!$P$28:$Q$31
Name AnsF: Lookups!$P$34:$P$37
Name AnsFTBL: Lookups!$P$34:$Q$37
Name AnsG: Lookups!$P$40:$P$43
Name AnsGTBL: Lookups!$P$40:$Q$43
Name AnsH: Lookups!$P$46:$P$49
Name AnsHTBL: Lookups!$P$46:$Q$49
Name AnsI: Lookups!$P$52:$P$55
Name AnsITBL: Lookups!$P$52:$Q$55
Name AnsJ: Lookups!$P$58:$P$61
Name AnsJTBL: Lookups!$P$58:$Q$61
Name AnsK: Lookups!$P$64:$P$67
Name AnsKTBL: Lookups!$P$64:$Q$67
Name AnsL: Lookups!$P$70:$P$73
Name AnsLTBL: Lookups!$P$70:$Q$73
Name AnsM: Lookups!$P$76:$P$79
Name AnsMTBL: Lookups!$P$76:$Q$79
Name AnsN: Lookups!$P$82:$P$85
Name AnsNTBL: Lookups!$P$82:$Q$85
Name AnsO: Lookups!$P$88:$P$91
Name AnsOTBL: Lookups!$P$88:$Q$91
Name AnsP: Lookups!$P$94:$P$97
Name AnsPTBL: Lookups!$P$94:$Q$97
Name AnsQ: Lookups!$P$100:$P$103
Name AnsQTBL: Lookups!$P$100:$Q$103
Name AnsR: Lookups!$P$106:$P$109
Name AnsRTBL: Lookups!$P$106:$Q$109
Name AnsS: Lookups!$P$112:$P$115
Name AnsSTBL: Lookups!$P$112:$Q$115
Name AnsT: Lookups!$P$118:$P$121
Name AnsTTBL: Lookups!$P$118:$Q$121
Name AnsU: Lookups!$P$124:$P$127
Name AnsUTBL: Lookups!$P$124:$Q$127
Name AnsV: Lookups!$P$130:$P$133
Name AnsVTBL: Lookups!$P$130:$Q$133
Name AnsW: Lookups!$P$136:$P$139
Name AnsWTBL: Lookups!$P$136:$Q$139
Name AnsX: Lookups!$P$142:$P$145
Name AnsXTBL: Lookups!$P$142:$Q$145
Name AnsY: Lookups!$P$148:$P$151
Name AnsYTBL: Lookups!$P$148:$Q$151
Name D_SA_A_1_1: #REF!
Name D_SA_A_1_1: '[1]DV-Lists'!$A$9:$A$13
Name D_SA_A_1_1: 'DV-Lists'!$A$9:$A$13
Name D_SA_A_2_1: #REF!
Name D_SA_A_2_1: '[1]DV-Lists'!$C$9:$C$13
Name D_SA_A_2_1: 'DV-Lists'!$C$9:$C$13
Name D_SA_A_3_1: #REF!
Name D_SA_A_3_1: '[1]DV-Lists'!$E$9:$E$13
Name D_SA_A_3_1: 'DV-Lists'!$E$9:$E$13
Name D_SA_B_1_1: #REF!

Sheet Attribution and License
A1: OWASP Software Assurance Maturity Model (SAMM)
A3: Version: | B3: 'v2.1.1
A5: Description: | B5: Our mission is to provide an effective and measurable way for all types of organizations to analyze and improve their software security posture. We want to raise awareness and educate organizations on how to design, develop, and deploy secure software through our self-assessment model.
A7: License: | B7: Creative Commons Attribution-ShareAlike 4.0 License
B8: This work is licensed under the Creative Commons Attribution-Share Alike 3.0 License. To view a copy of this license, visit http://creativecommons.org/licenses/by-sa/3.0/legalcode; or, (b) send a letter to Creative Commons, 171 2nd Street, Suite 300, San Francisco, California, 94105, USA.
A35: Element: | B35: Toolbox for v2.0
A36: Authors: | B36: Yan Kravchenko, multiple core team members
A37: Contributors: | B37: The SAMM project team
A39: Element: | B39: Toolbox for v1.5
A40: Authors: | B40: Brian Glas
A42: Element: | B42: Roadmap Chart Template v1.0
A43: Author: | B43: Colin Watson
A44: Contributors: | B44: Aidan Lynch
A46: Element: | B46: Interview Template v1.0
A47: Author(s): | B47: Nick Coblentz, Eoin Keary, and Seba Deleersnyder
A48: Contributors:
A50: SAMM | B50: The Software Assurance Maturity Model (SAMM) was created by Pravir Chandra and is now an Open Web Application Security Project (OWASP) project.
B51: SAMM is licensed under the Creative Commons Attribution-Share Alike 4.0 License
B52: https://owaspsamm.org/

Sheet Getting Started
A1: Action | C1: Description | D1: More details
A2: 1 | B2: Understand OWASP SAMM | C2: The Software Assurance Maturity Model (SAMM) provides an effective and measurable way to analyze and improve your software security posture. This spreadsheet is only an assessment tool and does not replace or summarize the model. In order to use this spreadsheet, you need to have familiarized yourself with the full the model. A free self-paced training is available to speed up your learning. | D2: https://www.youtube.com/watch?v=b8N8knQdbA4
D3: https://owaspsamm.org/model/
D4: https://owaspsamm.thinkific.com/courses/samm
A5: 2 | B5: Define the Scope | C5: Before starting, define your goals and decide whether you are assessing a specific application, a development team, or the entire organization. Consistency in scope is key to accurate results over time. | D5: https://owaspsamm.org/blog/2023/05/24/determining-scope-when-implementing-samm/
A6: 3 | B6: Conduct the Interview | C6: Go to the Interview sheet. Gather the relevant stakeholders (e.g., Lead Developers, Security Champions, Product Owners), organize workshops or interviews to capture input, and answer the multiple-choice questions for each Security Practice. Select the best matching answer from the drop-down lists and use the "Interview Notes" column to document context or justifications. | D6: https://owaspsamm.org/assessment-guide/
D7: https://owaspsamm.org/blog/2025/02/09/owasp-samm-skills-framework/
A8: 4 | B8: Review the Scorecard | C8: Once the interview is complete, switch to the Scorecard sheet. This is a read-only dashboard that automatically calculates your current maturity scores based on the answers provided in the Interview sheet.
A9: 5 | B9: Plan Your Roadmap | C9: Navigate to the Roadmap sheet to plan your improvement phases. You can set target maturity levels across different phases (Phase 1, 2, 3, etc.) and visualize your desired security journey in the Roadmap Chart sheet. | D9: https://owaspsamm.org/blog/2025/01/21/samm-relative-scoring/
A10: 6 | B10: Contribute to the Benchmark | C10: Help the OWASP community by anonymously sharing your assessment! Go to the Benchmark sheet, fill out the basic demographic data (your company name is not required), and follow the upload instructions to submit your file. This helps build industry-wide SAMM benchmarking statistics. | D10: https://owaspsamm.org/benchmark/

Sheet Benchmark
B1: This worksheet is for importing the data from this workbook into the SAMM Benchmarking system. Please complete the demographic data, all other data will auto-populate. | D1: To import this worksheet into your current SAMM worksheet follow these steps: 1. Have this workbook and your completed workbook open. 2. Right-clck the benchmark worksheet and choose "Move or Copy" 3. Change the workbook name to your SAMM workbook 4. Click Interview and check the box to make a copy 5. Once copied, open the Benchmark worksheet in your SAMM workbook 6. Click on the Formulas menu, and click "Show Formulas" 7. Ctrl-F and chose replace, enter in "[SAMM_spreadsheet]" and Replace All 8. Uncheck "Show Formulas", this should ensure that the auto linking is relative to your SAMM workbook. 9. Verify the scoring is represented in the table below. 10. Complete the demographic drop down selections. 11. Delete the company name if you desire before submission (it's not saved in the database either way) 12. Upload your file to https://bit.ly/sammbenchmarksubmission 13. An automated process will move the file into a secure Azure Blob for processing and remove the file. 14. Confirm the file is no longer visible in the folder you uploaded to after approximately 5 minutes. 15. If you have any issues or questions please email brian.glas@owasp.org
F2: Benchmark Lookups
F4: Type of Assessment | G4: Scope | H4: Region | I4: Industry | J4: Developers | K4: App Security | L4: Champions | M4: SDL
B5: Please complete this section | C5: Do not insert or delete lines | D5: Description | F5: Self-Assessment | G5: Company | H5: Africa | I5: Multiple | J5: 1-100 | K5: 1-5 | L5: 0 | M5: Waterfall
F6: Third-Party Assessment | G6: Organization | H6: Asia-Pacific | I6: Government | J6: 101-1000 | K6: 6-10 | L6: 1-20 | M6: AgileFall
B7: Version of SAMM | C7: ='Attribution and License'!B3 -> 'v2.1.1 | D7: Automatic from the Attribution Page | G7: Team | H7: Europe | I7: Critical Infrastructure | J7: 1001-10000 | K7: 11-20 | L7: 21-50 | M7: Agile
B8: Date of Assessment | C8: =Interview!D12 -> 0 | D8: Automatic from the Interview Page | H8: Latin America | I8: Defense | J8: 10000+ | K8: 20+ | L8: 51-100 | M8: Other
B9: Type of Assessment | D9: Choose the type of assessment | H9: North America | I9: Aerospace | L9: 100+
B10: Scope of Assessment | D10: Scope can be full org, a department/business unit/etc, or an individual team | H10: Global | I10: Automotive
B11: Geographic Region | D11: Select the best region | H11: Other | I11: Manufacturing
B12: Primary Industry | D12: Select the best fit for primary industry | I12: Healthcare
B13: Company Level of Developers | D13: How many developers within the company (estimated) | I13: Finance
B14: Company Level of App Security | D14: How many application security personnel in the company (estimated) | I14: Fintech
B15: Company Security Champions | D15: How many security champions in the company (estimated) | I15: IoT
B16: Target Level of Developers | D16: How many developers within the scope of the assessment (estimated) | I16: Cloud
B17: Primary SDL Methodology | D17: Primary software development methodology | I17: ISV
B18: Composite Score | C18: =Scorecard!J19 -> 0 | D18: Automatic from the Scorecard Sheet | I18: Retail
B19: Governance Score | C19: =Scorecard!J14 -> 0 | D19: Automatic from the Scorecard Sheet | I19: Other
B20: Design Score | C20: =Scorecard!J15 -> 0 | D20: Automatic from the Scorecard Sheet
B21: Implementation Score | C21: =Scorecard!J16 -> 0 | D21: Automatic from the Scorecard Sheet
B22: Verification Score | C22: =Scorecard!J17 -> 0 | D22: Automatic from the Scorecard Sheet
B23: Operations Score | C23: =Scorecard!J18 -> 0 | D23: Automatic from the Scorecard Sheet
B24: =Scorecard!B14 -> Strategy & Metrics | C24: =Scorecard!C14 -> 0 | D24: Automatic from the Scorecard Sheet
B25: =Scorecard!B15 -> Policy & Compliance | C25: =Scorecard!C15 -> 0 | D25: Automatic from the Scorecard Sheet
B26: =Scorecard!B16 -> Education & Guidance | C26: =Scorecard!C16 -> 0 | D26: Automatic from the Scorecard Sheet
B27: =Scorecard!B17 -> Threat Assessment | C27: =Scorecard!C17 -> 0 | D27: Automatic from the Scorecard Sheet
B28: =Scorecard!B18 -> Security Requirements | C28: =Scorecard!C18 -> 0 | D28: Automatic from the Scorecard Sheet
B29: =Scorecard!B19 -> Secure Architecture | C29: =Scorecard!C19 -> 0 | D29: Automatic from the Scorecard Sheet
B30: =Scorecard!B20 -> Secure Build | C30: =Scorecard!C20 -> 0 | D30: Automatic from the Scorecard Sheet
B31: =Scorecard!B21 -> Secure Deployment | C31: =Scorecard!C21 -> 0 | D31: Automatic from the Scorecard Sheet
B32: =Scorecard!B22 -> Defect Management | C32: =Scorecard!C22 -> 0 | D32: Automatic from the Scorecard Sheet
B33: =Scorecard!B23 -> Architecture Assessment | C33: =Scorecard!C23 -> 0 | D33: Automatic from the Scorecard Sheet
B34: =Scorecard!B24 -> Requirements Testing | C34: =Scorecard!C24 -> 0 | D34: Automatic from the Scorecard Sheet
B35: =Scorecard!B25 -> Security Testing | C35: =Scorecard!C25 -> 0 | D35: Automatic from the Scorecard Sheet
... B38: =Scorecard!B28 -> Operational Management | C38: =Scorecard!C28 -> 0 | D38: Automatic from the Scorecard Sheet
B39: G-SM-A-1-1 | C39: =VLOOKUP(B39,Interview!$A$18:$J$230,7,FALSE) -> 0 | D39: Automatic from the Interview Sheet
B40: G-SM-A-2-1 | C40: =VLOOKUP(B40,Interview!$A$18:$J$230,7,FALSE) -> 0 | D40: Automatic from the Interview Sheet
B41: G-SM-A-3-1 | C41: =VLOOKUP(B41,Interview!$A$18:$J$230,7,FALSE) -> 0 | D41: Automatic from the Interview Sheet
B42: G-SM-B-1-1 | C42: =VLOOKUP(B42,Interview!$A$18:$J$230,7,FALSE) -> 0 | D42: Automatic from the Interview Sheet
B43: G-SM-B-2-1 | C43: =VLOOKUP(B43,Interview!$A$18:$J$230,7,FALSE) -> 0 | D43: Automatic from the Interview Sheet
...

Sheet Interview
B1: =CONCATENATE("SAMM Assessment Interview: ",D11," For ",D10) -> SAMM Assessment Interview: For
B3: Instructions
B4: Interview an individual based on the questions below organized according to SAMM Business Functions and Security Practices.
B5: Select the best answer from the multiple choice drop down selections in the answer column.
B6: Document additional information such as how and why in the "Interview Notes" column.
B7: The formulas in hidden columns F-H will calculate the scores and update the Rating boxes and other worksheets as needed.
B8: Once the interview is complete, go to the "Scorecard" sheet and follow instructions.
B10: Organization:
B11: Team/Application:
B12: Interview Date:
B13: Team Lead:
B14: Contributors:
B16: Governance
B17: Stream | C17: Level | D17: Strategy & Metrics | F17: Answer | I17: Interview Notes | J17: Rating
A18: G-SM-A-1-1 | B18: =INDEX('imp-questions'!D:D, MATCH(A18, 'imp-questions'!A:A, 0)) -> Create and Promote | C18: =INDEX('imp-questions'!E:E, MATCH(A18, 'imp-questions'!A:A, 0)) -> 1 | D18: =INDEX('imp-questions'!F:F, MATCH(A18, 'imp-questions'!A:A, 0)) -> Do you understand the enterprise-wide risk appetite for your applications? | E18: =CHAR(65+INDEX('imp-questions'!H:H, MATCH(A18, 'imp-questions'!A:A, 0))) -> N | G18: =IFERROR(INDEX(INDIRECT("Ans" & E18 & "TBL"), MATCH(F18, INDEX(INDIRECT("Ans" & E18 & "TBL"), 0, 1), 0), 2), 0) -> 0 | H18: =IFERROR(AVERAGE(G18,G25),0) -> 0 | J18: =SUM(H18,H20,H22) -> 0
D19: =INDEX('imp-questions'!G:G, MATCH(A18, 'imp-questions'!A:A, 0)) -> You capture the risk appetite of your organization's executive leadership The organization's leadership vet and approve the set of risks You identify the main business and technical threats to your assets and data You document risks and store them in an accessible location
A20: G-SM-A-2-1 | C20: =INDEX('imp-questions'!E:E, MATCH(A20, 'imp-questions'!A:A, 0)) -> 2 | D20: =INDEX('imp-questions'!F:F, MATCH(A20, 'imp-questions'!A:A, 0)) -> Do you have a strategic plan for application security and use it to make decisions? | E20: =CHAR(65+INDEX('imp-questions'!H:H, MATCH(A20, 'imp-questions'!A:A, 0))) -> O | G20: =IFERROR(INDEX(INDIRECT("Ans" & E20 & "TBL"), MATCH(F20, INDEX(INDIRECT("Ans" & E20 & "TBL"), 0, 1), 0), 2), 0) -> 0 | H20: =IFERROR(AVERAGE(G20,G27),0) -> 0
D21: =INDEX('imp-questions'!G:G, MATCH(A20, 'imp-questions'!A:A, 0)) -> The plan reflects the organization's business priorities and risk appetite The plan includes measurable milestones and a budget The plan is consistent with the organization's business drivers and risks The plan lays out a roadmap for strategic and tactical initiatives You have buy-in from stakeholders, including development teams
A22: G-SM-A-3-1 | C22: =INDEX('imp-questions'!E:E, MATCH(A22, 'imp-questions'!A:A, 0)) -> 3 | D22: =INDEX('imp-questions'!F:F, MATCH(A22, 'imp-questions'!A:A, 0)) -> Do you regularly review and update the Strategic Plan for Application Security? | E22: =CHAR(65+INDEX('imp-questions'!H:H, MATCH(A22, 'imp-questions'!A:A, 0))) -> P | G22: =IFERROR(INDEX(INDIRECT("Ans" & E22 & "TBL"), MATCH(F22, INDEX(INDIRECT("Ans" & E22 & "TBL"), 0, 1), 0), 2), 0) -> 0 | H22: =IFERROR(AVERAGE(G22,G29),0) -> 0
D23: =INDEX('imp-questions'!G:G, MATCH(A22, 'imp-questions'!A:A, 0)) -> You review and update the plan in response to significant changes in the business environment, the organization, or its risk appetite Plan update steps include reviewing the plan with all the stakeholders and updating the business drivers and strategies You adjust the plan and roadmap based on lessons learned from completed roadmap activities You publish progress information on roadmap activities, making sure they are available to all stakeholders
A25: G-SM-B-1-1 | B25: =INDEX('imp-questions'!D:D, MATCH(A25, 'imp-questions'!A:A, 0)) -> Measure and Improve | C25: =INDEX('imp-questions'!E:E, MATCH(A25, 'imp-questions'!A:A, 0)) -> 1 | D25: =INDEX('imp-questions'!F:F, MATCH(A25, 'imp-questions'!A:A, 0)) -> Do you use a set of metrics to measure the effectiveness and efficiency of the application security program across applications? | E25: =CHAR(65+INDEX('imp-questions'!H:H, MATCH(A25, 'imp-questions'!A:A, 0))) -> Q | G25: =IFERROR(INDEX(INDIRECT("Ans" & E25 & "TBL"), MATCH(F25, INDEX(INDIRECT("Ans" & E25 & "TBL"), 0, 1), 0), 2), 0) -> 0
D26: =INDEX('imp-questions'!G:G, MATCH(A25, 'imp-questions'!A:A, 0)) -> You document each metric, including a description of the sources, measurement coverage, and guidance on how to use it to explain application security trends Metrics include measures of efforts, results, and the environment measurement categories Most of the metrics are frequently measured, easy or inexpensive to gather, and expressed as a cardinal number or a percentage Application security and development teams publish metrics
A27: G-SM-B-2-1 | C27: =INDEX('imp-questions'!E:E, MATCH(A27, 'imp-questions'!A:A, 0)) -> 2 | D27: =INDEX('imp-questions'!F:F, MATCH(A27, 'imp-questions'!A:A, 0)) -> Did you define Key Performance Indicators (KPI) from available application security metrics? | E27: =CHAR(65+INDEX('imp-questions'!H:H, MATCH(A27, 'imp-questions'!A:A, 0))) -> S | G27: =IFERROR(INDEX(INDIRECT("Ans" & E27 & "TBL"), MATCH(F27, INDEX(INDIRECT("Ans" & E27 & "TBL"), 0, 1), 0), 2), 0) -> 0
D28: =INDEX('imp-questions'!G:G, MATCH(A27, 'imp-questions'!A:A, 0)) -> You defined KPIs after gathering enough information to establish realistic objectives You developed KPIs with the buy-in from the leadership and teams responsible for application security KPIs are available to the application teams and include acceptability thresholds and guidance in case teams need to take action Success of the application security program is clearly visible based on defined KPIs
A29: G-SM-B-3-1 | C29: =INDEX('imp-questions'!E:E, MATCH(A29, 'imp-questions'!A:A, 0)) -> 3 | D29: =INDEX('imp-questions'!F:F, MATCH(A29, 'imp-questions'!A:A, 0)) -> Do you update the Application Security strategy and roadmap based on application security metrics and KPIs? | E29: =CHAR(65+INDEX('imp-questions'!H:H, MATCH(A29, 'imp-questions'!A:A, 0))) -> P | G29: =IFERROR(INDEX(INDIRECT("Ans" & E29 & "TBL"), MATCH(F29, INDEX(INDIRECT("Ans" & E29 & "TBL"), 0, 1), 0), 2), 0) -> 0
D30: =INDEX('imp-questions'!G:G, MATCH(A29, 'imp-questions'!A:A, 0)) -> You review KPIs at least yearly for their efficiency and effectiveness KPIs and application security metrics trigger most of the changes to the application security strategy
B31: Policy & Compliance | F31: Answer | I31: Interview Notes | J31: Rating
A32: G-PC-A-1-1 | B32: =INDEX('imp-questions'!D:D, MATCH(A32, 'imp-questions'!A:A, 0)) -> Policy and Standards | C32: =INDEX('imp-questions'!E:E, MATCH(A32, 'imp-questions'!A:A, 0)) -> 1 | D32: =INDEX('imp-questions'!F:F, MATCH(A32, 'imp-questions'!A:A, 0)) -> Do you have and apply a common set of policies and standards throughout your organization? | E32: =CHAR(65+INDEX('imp-questions'!H:H, MATCH(A32, 'imp-questions'!A:A, 0))) -> A | G32: =IFERROR(INDEX(INDIRECT("Ans" & E32 & "TBL"), MATCH(F32, INDEX(INDIRECT("Ans" & E32 & "TBL"), 0, 1), 0), 2), 0) -> 0 | H32: =IFERROR(AVERAGE(G32,G39),0) -> 0 | J32: =SUM(H32,H34,H36) -> 0
D33: =INDEX('imp-questions'!G:G, MATCH(A32, 'imp-questions'!A:A, 0)) -> You have adapted existing standards appropriate for the organization’s industry to account for domain-specific considerations Your standards are aligned with your policies and incorporate technology-specific implementation guidance
A34: G-PC-A-2-1 | C34: =INDEX('imp-questions'!E:E, MATCH(A34, 'imp-questions'!A:A, 0)) -> 2 | D34: =INDEX('imp-questions'!F:F, MATCH(A34, 'imp-questions'!A:A, 0)) -> Do you publish the organization's policies as test scripts or run-books for easy interpretation by development teams? | E34: =CHAR(65+INDEX('imp-questions'!H:H, MATCH(A34, 'imp-questions'!A:A, 0))) -> C | G34: =IFERROR(INDEX(INDIRECT("Ans" & E34 & "TBL"), MATCH(F34, INDEX(INDIRECT("Ans" & E34 & "TBL"), 0, 1), 0), 2), 0) -> 0 | H34: =IFERROR(AVERAGE(G34,G41),0) -> 0
D35: =INDEX('imp-questions'!G:G, MATCH(A34, 'imp-questions'!A:A, 0)) -> You create verification checklists and test scripts where applicable, aligned with the policy's requirements and the implementation guidance in the associated standards You create versions adapted to each development methodology and technology the organization uses
A36: G-PC-A-3-1 | C36: =INDEX('imp-questions'!E:E, MATCH(A36, 'imp-questions'!A:A, 0)) -> 3 | D36: =INDEX('imp-questions'!F:F, MATCH(A36, 'imp-questions'!A:A, 0)) -> Do you regularly report on policy and standard compliance, and use that information to guide compliance improvement efforts? | E36: =CHAR(65+INDEX('imp-questions'!H:H, MATCH(A36, 'imp-questions'!A:A, 0))) -> T | G36: =IFERROR(INDEX(INDIRECT("Ans" & E36 & "TBL"), MATCH(F36, INDEX(INDIRECT("Ans" & E36 & "TBL"), 0, 1), 0), 2), 0) -> 0 | H36: =IFERROR(AVERAGE(G36,G43),0) -> 0
D37: =INDEX('imp-questions'!G:G, MATCH(A36, 'imp-questions'!A:A, 0)) -> You have procedures (automated, if possible) to regularly generate compliance reports You deliver compliance reports to all relevant stakeholders Stakeholders use the reported compliance status information to identify areas for improvement
A39: G-PC-B-1-1 | B39: =INDEX('imp-questions'!D:D, MATCH(A39, 'imp-questions'!A:A, 0)) -> Compliance Management | C39: =INDEX('imp-questions'!E:E, MATCH(A39, 'imp-questions'!A:A, 0)) -> 1 | D39: =INDEX('imp-questions'!F:F, MATCH(A39, 'imp-questions'!A:A, 0)) -> Do you have a complete picture of your external compliance obligations? | E39: =CHAR(65+INDEX('imp-questions'!H:H, MATCH(A39, 'imp-questions'!A:A, 0))) -> A | G39: =IFERROR(INDEX(INDIRECT("Ans" & E39 & "TBL"), MATCH(F39, INDEX(INDIRECT("Ans" & E39 & "TBL"), 0, 1), 0), 2), 0) -> 0
D40: =INDEX('imp-questions'!G:G, MATCH(A39, 'imp-questions'!A:A, 0)) -> You have identified all sources of external compliance obligations You have captured and reconciled compliance obligations from all sources
A41: G-PC-B-2-1 | C41: =INDEX('imp-questions'!E:E, MATCH(A41, 'imp-questions'!A:A, 0)) -> 2 | D41: =INDEX('imp-questions'!F:F, MATCH(A41, 'imp-questions'!A:A, 0)) -> Do you have a standard set of security requirements and verification procedures addressing the organization's external compliance obligations? | E41: =CHAR(65+INDEX('imp-questions'!H:H, MATCH(A41, 'imp-questions'!A:A, 0))) -> U | G41: =IFERROR(INDEX(INDIRECT("Ans" & E41 & "TBL"), MATCH(F41, INDEX(INDIRECT("Ans" & E41 & "TBL"), 0, 1), 0), 2), 0) -> 0
D42: =INDEX('imp-questions'!G:G, MATCH(A41, 'imp-questions'!A:A, 0)) -> You map each external compliance obligation to a well-defined set of application requirements You define verification procedures, including automated tests, to verify compliance with compliance-related requirements
A43: G-PC-B-3-1 | C43: =INDEX('imp-questions'!E:E, MATCH(A43, 'imp-questions'!A:A, 0)) -> 3 | D43: =INDEX('imp-questions'!F:F, MATCH(A43, 'imp-questions'!A:A, 0)) -> Do you regularly report on adherence to external compliance obligations and use that information to guide efforts to close compliance gaps? | E43: =CHAR(65+INDEX('imp-questions'!H:H, MATCH(A43, 'imp-questions'!A:A, 0))) -> T | G43: =IFERROR(INDEX(INDIRECT("Ans" & E43 & "TBL"), MATCH(F43, INDEX(INDIRECT("Ans" & E43 & "TBL"), 0, 1), 0), 2), 0) -> 0
D44: =INDEX('imp-questions'!G:G, MATCH(A43, 'imp-questions'!A:A, 0)) -> You have established, well-defined compliance metrics You measure and report on applications' compliance metrics regularly Stakeholders use the reported compliance status information to identify compliance gaps and prioritize gap remediation efforts
B45: Education & Guidance | F45: Answer | I45: Interview Notes | J45: Rating
...

Sheet Scorecard
A1: =CONCATENATE("SAMM Assessment Scorecard: ",C6," For ",C5) -> SAMM Assessment Scorecard: For
A3: Notes: Data in this worksheet is automatically imported from the Interview and Roadmap worksheets and will automatically update when changed in the respective worksheets. This is mostly a read-only worksheet, changes should be made in Interview or Roadmap worksheets.
A5: =Interview!B10 -> Organization: | C5: =IF(ISBLANK(Interview!D10),"",Interview!D10)
A6: =Interview!B11 -> Team/Application: | C6: =IF(ISBLANK(Interview!D11),"",Interview!D11)
A7: =Interview!B12 -> Interview Date: | C7: =IF(ISBLANK(Interview!D12),"",Interview!D12)
A8: =Interview!B13 -> Team Lead: | C8: =IF(ISBLANK(Interview!D13),"",Interview!D13)
A9: =Interview!B14 -> Contributors: | C9: =IF(ISBLANK(Interview!D14),"",Interview!D14)
A11: Current Maturity Score | L11: Current Maturity Score | T11: Current Maturity Score
D12: Maturity
A13: Business Functions | B13: Security Practices | C13: Score | D13: 1 | E13: 2 | F13: 3 | G13: Translated Value | I13: Business Functions | J13: Score | V13: =T14 -> Governance | W13: =T17 -> Design | X13: =T20 -> Implementation | Y13: =T23 -> Verification | Z13: =T26 -> Operations
A14: =Interview!$B$16 -> Governance | B14: =Interview!$D$17 -> Strategy & Metrics | C14: =Interview!$J$18 -> 0 | D14: =Interview!H18 -> 0 | E14: =Interview!H20 -> 0 | F14: =Interview!H22 -> 0 | G14: =(((((IF((C14="0+"),0.5,0)+IF((C14=1),1,0))+IF((C14="1+"),1.5,0))+IF((C14=2),2,0))+IF((C14="2+"),2.5,0))+IF((C14=3),3,0))+IF((C14="3+"),3.5,0) -> 0 | I14: =A14 -> Governance | J14: =AVERAGE(C14:C16) -> 0 | T14: =A14 -> Governance | U14: =B14 -> Strategy & Metrics | V14: =C14 -> 0 | W14: 0 | X14: 0 | Y14: 0 | Z14: 0
A15: =Interview!$B$16 -> Governance | B15: =Interview!$B$31 -> Policy & Compliance | C15: =Interview!$J$32 -> 0 | D15: =Interview!H32 -> 0 | E15: =Interview!H34 -> 0 | F15: =Interview!H36 -> 0 | G15: =(((((IF((C15="0+"),0.5,0)+IF((C15=1),1,0))+IF((C15="1+"),1.5,0))+IF((C15=2),2,0))+IF((C15="2+"),2.5,0))+IF((C15=3),3,0))+IF((C15="3+"),3.5,0) -> 0 | I15: =A17 -> Design | J15: =AVERAGE(C17:C19) -> 0 | T15: =A15 -> Governance | U15: =B15 -> Policy & Compliance | V15: =C15 -> 0 | W15: 0 | X15: 0 | Y15: 0 | Z15: 0
A16: =Interview!$B$16 -> Governance | B16: =Interview!$B$45 -> Education & Guidance | C16: =Interview!$J$46 -> 0 | D16: =Interview!H46 -> 0 | E16: =Interview!H48 -> 0 | F16: =Interview!H50 -> 0 | G16: =(((((IF((C16="0+"),0.5,0)+IF((C16=1),1,0))+IF((C16="1+"),1.5,0))+IF((C16=2),2,0))+IF((C16="2+"),2.5,0))+IF((C16=3),3,0))+IF((C16="3+"),3.5,0) -> 0 | I16: =A20 -> Implementation | J16: =AVERAGE(C20:C22) -> 0 | T16: =A16 -> Governance | U16: =B16 -> Education & Guidance | V16: =C16 -> 0 | W16: 0 | X16: 0 | Y16: 0 | Z16: 0
A17: =Interview!$B$59 -> Design | B17: =Interview!$B$60 -> Threat Assessment | C17: =Interview!$J$61 -> 0 | D17: =Interview!H61 -> 0 | E17: =Interview!H63 -> 0 | F17: =Interview!H65 -> 0 | G17: =(((((IF((C17="0+"),0.5,0)+IF((C17=1),1,0))+IF((C17="1+"),1.5,0))+IF((C17=2),2,0))+IF((C17="2+"),2.5,0))+IF((C17=3),3,0))+IF((C17="3+"),3.5,0) -> 0 | I17: =A23 -> Verification | J17: =AVERAGE(C23:C25) -> 0 | T17: =A17 -> Design | U17: =B17 -> Threat Assessment | V17: 0 | W17: =C17 -> 0 | X17: 0 | Y17: 0 | Z17: 0
A18: =Interview!$B$59 -> Design | B18: =Interview!$B$74 -> Security Requirements | C18: =Interview!$J$75 -> 0 | D18: =Interview!H75 -> 0 | E18: =Interview!H77 -> 0 | F18: =Interview!H79 -> 0 | G18: =(((((IF((C18="0+"),0.5,0)+IF((C18=1),1,0))+IF((C18="1+"),1.5,0))+IF((C18=2),2,0))+IF((C18="2+"),2.5,0))+IF((C18=3),3,0))+IF((C18="3+"),3.5,0) -> 0 | I18: =A26 -> Operations | J18: =AVERAGE(C26:C28) -> 0 | T18: =A18 -> Design | U18: =B18 -> Security Requirements | V18: 0 | W18: =C18 -> 0 | X18: 0 | Y18: 0 | Z18: 0
A19: =Interview!$B$59 -> Design | B19: =Interview!$B$88 -> Secure Architecture | C19: =Interview!$J$89 -> 0 | D19: =Interview!H89 -> 0 | E19: =Interview!H91 -> 0 | F19: =Interview!H93 -> 0 | G19: =(((((IF((C19="0+"),0.5,0)+IF((C19=1),1,0))+IF((C19="1+"),1.5,0))+IF((C19=2),2,0))+IF((C19="2+"),2.5,0))+IF((C19=3),3,0))+IF((C19="3+"),3.5,0) -> 0 | I19: Overall | J19: =AVERAGE(J14:J18) -> 0 | T19: =A19 -> Design | U19: =B19 -> Secure Architecture | V19: 0 | W19: =C19 -> 0 | X19: 0 | Y19: 0 | Z19: 0
A20: =Interview!$B$102 -> Implementation | B20: =Interview!$B$103 -> Secure Build | C20: =Interview!$J$104 -> 0 | D20: =Interview!H104 -> 0 | E20: =Interview!H106 -> 0 | F20: =Interview!H108 -> 0 | G20: =(((((IF((C20="0+"),0.5,0)+IF((C20=1),1,0))+IF((C20="1+"),1.5,0))+IF((C20=2),2,0))+IF((C20="2+"),2.5,0))+IF((C20=3),3,0))+IF((C20="3+"),3.5,0) -> 0 | T20: =A20 -> Implementation | U20: =B20 -> Secure Build | V20: 0 | W20: 0 | X20: =C20 -> 0 | Y20: 0 | Z20: 0
A21: =Interview!$B$102 -> Implementation | B21: =Interview!$B$117 -> Secure Deployment | C21: =Interview!$J$118 -> 0 | D21: =Interview!H118 -> 0 | E21: =Interview!H120 -> 0 | F21: =Interview!H122 -> 0 | G21: =(((((IF((C21="0+"),0.5,0)+IF((C21=1),1,0))+IF((C21="1+"),1.5,0))+IF((C21=2),2,0))+IF((C21="2+"),2.5,0))+IF((C21=3),3,0))+IF((C21="3+"),3.5,0) -> 0 | T21: =A21 -> Implementation | U21: =B21 -> Secure Deployment | V21: 0 | W21: 0 | X21: =C21 -> 0 | Y21: 0 | Z21: 0
A22: =Interview!$B$102 -> Implementation | B22: =Interview!$B$131 -> Defect Management | C22: =Interview!$J$132 -> 0 | D22: =Interview!H132 -> 0 | E22: =Interview!H134 -> 0 | F22: =Interview!H136 -> 0 | G22: =(((((IF((C22="0+"),0.5,0)+IF((C22=1),1,0))+IF((C22="1+"),1.5,0))+IF((C22=2),2,0))+IF((C22="2+"),2.5,0))+IF((C22=3),3,0))+IF((C22="3+"),3.5,0) -> 0 | T22: =A22 -> Implementation | U22: =B22 -> Defect Management | V22: 0 | W22: 0 | X22: =C22 -> 0 | Y22: 0 | Z22: 0
A23: =Interview!$B$145 -> Verification | B23: =Interview!$B$146 -> Architecture Assessment | C23: =Interview!$J$147 -> 0 | D23: =Interview!H147 -> 0 | E23: =Interview!H149 -> 0 | F23: =Interview!H151 -> 0 | G23: =(((((IF((C23="0+"),0.5,0)+IF((C23=1),1,0))+IF((C23="1+"),1.5,0))+IF((C23=2),2,0))+IF((C23="2+"),2.5,0))+IF((C23=3),3,0))+IF((C23="3+"),3.5,0) -> 0 | T23: =A23 -> Verification | U23: =B23 -> Architecture Assessment | V23: 0 | W23: 0 | X23: 0 | Y23: =C23 -> 0 | Z23: 0
A24: =Interview!$B$145 -> Verification | B24: =Interview!$B$160 -> Requirements Testing | C24: =Interview!$J$161 -> 0 | D24: =Interview!H161 -> 0 | E24: =Interview!H163 -> 0 | F24: =Interview!H165 -> 0 | G24: =(((((IF((C24="0+"),0.5,0)+IF((C24=1),1,0))+IF((C24="1+"),1.5,0))+IF((C24=2),2,0))+IF((C24="2+"),2.5,0))+IF((C24=3),3,0))+IF((C24="3+"),3.5,0) -> 0 | T24: =A24 -> Verification | U24: =B24 -> Requirements Testing | V24: 0 | W24: 0 | X24: 0 | Y24: =C24 -> 0 | Z24: 0
A25: =Interview!$B$145 -> Verification | B25: =Interview!$B$174 -> Security Testing | C25: =Interview!$J$175 -> 0 | D25: =Interview!H175 -> 0 | E25: =Interview!H177 -> 0 | F25: =Interview!H179 -> 0 | G25: =(((((IF((C25="0+"),0.5,0)+IF((C25=1),1,0))+IF((C25="1+"),1.5,0))+IF((C25=2),2,0))+IF((C25="2+"),2.5,0))+IF((C25=3),3,0))+IF((C25="3+"),3.5,0) -> 0 | T25: =A25 -> Verification | U25: =B25 -> Security Testing | V25: 0 | W25: 0 | X25: 0 | Y25: =C25 -> 0 | Z25: 0
A26: =Interview!$B$188 -> Operations | B26: =Interview!$B$189 -> Incident Management | C26: =Interview!$J$190 -> 0 | D26: =Interview!H190 -> 0 | E26: =Interview!H192 -> 0 | F26: =Interview!H194 -> 0 | G26: =(((((IF((C26="0+"),0.5,0)+IF((C26=1),1,0))+IF((C26="1+"),1.5,0))+IF((C26=2),2,0))+IF((C26="2+"),2.5,0))+IF((C26=3),3,0))+IF((C26="3+"),3.5,0) -> 0 | T26: =A26 -> Operations | U26: =B26 -> Incident Management | V26: 0 | W26: 0 | X26: 0 | Y26: 0 | Z26: =C26 -> 0
A27: =Interview!$B$188 -> Operations | B27: =Interview!$B$203 -> Environment Management | C27: =Interview!$J$204 -> 0 | D27: =Interview!H204 -> 0 | E27: =Interview!H206 -> 0 | F27: =Interview!H208 -> 0 | G27: =(((((IF((C27="0+"),0.5,0)+IF((C27=1),1,0))+IF((C27="1+"),1.5,0))+IF((C27=2),2,0))+IF((C27="2+"),2.5,0))+IF((C27=3),3,0))+IF((C27="3+"),3.5,0) -> 0 | T27: =A27 -> Operations | U27: =B27 -> Environment Management | V27: 0 | W27: 0 | X27: 0 | Y27: 0 | Z27: =C27 -> 0
A28: =Interview!$B$188 -> Operations | B28: =Interview!$B$217 -> Operational Management | C28: =Interview!$J$218 -> 0 | D28: =Interview!H218 -> 0 | E28: =Interview!H220 -> 0 | F28: =Interview!H222 -> 0 | G28: =(((((IF((C28="0+"),0.5,0)+IF((C28=1),1,0))+IF((C28="1+"),1.5,0))+IF((C28=2),2,0))+IF((C28="2+"),2.5,0))+IF((C28=3),3,0))+IF((C28="3+"),3.5,0) -> 0 | T28: =A28 -> Operations | U28: =B28 -> Operational Management | V28: 0 | W28: 0 | X28: 0 | Y28: 0 | Z28: =C28 -> 0
A31: Phase 1 Maturity Score | L31: Phase 1 Maturity Score | T31: Phase 1 Maturity Score
D32: Maturity
A33: Business Functions | B33: Security Practices | C33: Score | D33: 1 | E33: 2 | F33: 3 | G33: Translated Value | I33: Business Functions | J33: Score | V33: =T34 -> Governance | W33: =T37 -> Design | X33: =T40 -> Implementation | Y33: =T43 -> Verification | Z33: =T46 -> Operations
A34: =Interview!$B$16 -> Governance | B34: =Interview!$D$17 -> Strategy & Metrics | C34: =Roadmap!M18 -> 0 | D34: =Roadmap!L18 -> 0 | E34: =Roadmap!L19 -> 0 | F34: =Roadmap!L20 -> 0 | G34: =(((((IF((C34="0+"),0.5,0)+IF((C34=1),1,0))+IF((C34="1+"),1.5,0))+IF((C34=2),2,0))+IF((C34="2+"),2.5,0))+IF((C34=3),3,0))+IF((C34="3+"),3.5,0) -> 0 | I34: =A34 -> Governance | J34: =AVERAGE(C34:C36) -> 0 | T34: =Interview!$B$16 -> Governance | U34: =Interview!$D$17 -> Strategy & Metrics | V34: =C34 -> 0 | W34: 0 | X34: 0 | Y34: 0 | Z34: 0
A35: =Interview!$B$16 -> Governance | B35: =Interview!$B$31 -> Policy & Compliance | C35: =Roadmap!M27 -> 0 | D35: =Roadmap!L27 -> 0 | E35: =Roadmap!L28 -> 0 | F35: =Roadmap!L29 -> 0 | G35: =(((((IF((C35="0+"),0.5,0)+IF((C35=1),1,0))+IF((C35="1+"),1.5,0))+IF((C35=2),2,0))+IF((C35="2+"),2.5,0))+IF((C35=3),3,0))+IF((C35="3+"),3.5,0) -> 0 | I35: =A37 -> Design | J35: =AVERAGE(C37:C39) -> 0 | T35: =Interview!$B$16 -> Governance | U35: =Interview!$B$31 -> Policy & Compliance | V35: =C35 -> 0 | W35: 0 | X35: 0 | Y35: 0 | Z35: 0
A36: =Interview!$B$16 -> Governance | B36: =Interview!$B$45 -> Education & Guidance | C36: =Roadmap!M36 -> 0 | D36: =Roadmap!L36 -> 0 | E36: =Roadmap!L37 -> 0 | F36: =Roadmap!L38 -> 0 | G36: =(((((IF((C36="0+"),0.5,0)+IF((C36=1),1,0))+IF((C36="1+"),1.5,0))+IF((C36=2),2,0))+IF((C36="2+"),2.5,0))+IF((C36=3),3,0))+IF((C36="3+"),3.5,0) -> 0 | I36: =A40 -> Implementation | J36: =AVERAGE(C40:C42) -> 0 | T36: =Interview!$B$16 -> Governance | U36: =Interview!$B$45 -> Education & Guidance | V36: =C36 -> 0 | W36: 0 | X36: 0 | Y36: 0 | Z36: 0
A37: =Interview!$B$59 -> Design | B37: =Interview!$B$60 -> Threat Assessment | C37: =Roadmap!M46 -> 0 | D37: =Roadmap!L46 -> 0 | E37: =Roadmap!L47 -> 0 | F37: =Roadmap!L48 -> 0 | G37: =(((((IF((C37="0+"),0.5,0)+IF((C37=1),1,0))+IF((C37="1+"),1.5,0))+IF((C37=2),2,0))+IF((C37="2+"),2.5,0))+IF((C37=3),3,0))+IF((C37="3+"),3.5,0) -> 0 | I37: =A43 -> Verification | J37: =AVERAGE(C43:C45) -> 0 | T37: =Interview!$B$59 -> Design | U37: =Interview!$B$60 -> Threat Assessment | V37: 0 | W37: =C37 -> 0 | X37: 0 | Y37: 0 | Z37: 0
A38: =Interview!$B$59 -> Design | B38: =Interview!$B$74 -> Security Requirements | C38: =Roadmap!M55 -> 0 | D38: =Roadmap!L55 -> 0 | E38: =Roadmap!L56 -> 0 | F38: =Roadmap!L57 -> 0 | G38: =(((((IF((C38="0+"),0.5,0)+IF((C38=1),1,0))+IF((C38="1+"),1.5,0))+IF((C38=2),2,0))+IF((C38="2+"),2.5,0))+IF((C38=3),3,0))+IF((C38="3+"),3.5,0) -> 0 | I38: =A46 -> Operations | J38: =AVERAGE(C46:C48) -> 0 | T38: =Interview!$B$59 -> Design | U38: =Interview!$B$74 -> Security Requirements | V38: 0 | W38: =C38 -> 0 | X38: 0 | Y38: 0 | Z38: 0
A39: =Interview!$B$59 -> Design | B39: =Interview!$B$88 -> Secure Architecture | C39: =Roadmap!M64 -> 0 | D39: =Roadmap!L64 -> 0 | E39: =Roadmap!L65 -> 0 | F39: =Roadmap!L66 -> 0 | G39: =(((((IF((C39="0+"),0.5,0)+IF((C39=1),1,0))+IF((C39="1+"),1.5,0))+IF((C39=2),2,0))+IF((C39="2+"),2.5,0))+IF((C39=3),3,0))+IF((C39="3+"),3.5,0) -> 0 | I39: Overall | J39: =AVERAGE(J34:J38) -> 0 | T39: =Interview!$B$59 -> Design | U39: =Interview!$B$88 -> Secure Architecture | V39: 0 | W39: =C39 -> 0 | X39: 0 | Y39: 0 | Z39: 0
A40: =Interview!$B$102 -> Implementation | B40: =Interview!$B$103 -> Secure Build | C40: =Roadmap!M74 -> 0 | D40: =Roadmap!L74 -> 0 | E40: =Roadmap!L75 -> 0 | F40: =Roadmap!L76 -> 0 | G40: =(((((IF((C40="0+"),0.5,0)+IF((C40=1),1,0))+IF((C40="1+"),1.5,0))+IF((C40=2),2,0))+IF((C40="2+"),2.5,0))+IF((C40=3),3,0))+IF((C40="3+"),3.5,0) -> 0 | T40: =Interview!$B$102 -> Implementation | U40: =Interview!$B$103 -> Secure Build | V40: 0 | W40: 0 | X40: =C40 -> 0 | Y40: 0 | Z40: 0
A41: =Interview!$B$102 -> Implementation | B41: =Interview!$B$117 -> Secure Deployment | C41: =Roadmap!M83 -> 0 | D41: =Roadmap!L83 -> 0 | E41: =Roadmap!L84 -> 0 | F41: =Roadmap!L85 -> 0 | G41: =(((((IF((C41="0+"),0.5,0)+IF((C41=1),1,0))+IF((C41="1+"),1.5,0))+IF((C41=2),2,0))+IF((C41="2+"),2.5,0))+IF((C41=3),3,0))+IF((C41="3+"),3.5,0) -> 0 | T41: =Interview!$B$102 -> Implementation | U41: =Interview!$B$117 -> Secure Deployment | V41: 0 | W41: 0 | X41: =C41 -> 0 | Y41: 0 | Z41: 0
A42: =Interview!$B$102 -> Implementation | B42: =Interview!$B$131 -> Defect Management | C42: =Roadmap!M92 -> 0 | D42: =Roadmap!L92 -> 0 | E42: =Roadmap!L93 -> 0 | F42: =Roadmap!L94 -> 0 | G42: =(((((IF((C42="0+"),0.5,0)+IF((C42=1),1,0))+IF((C42="1+"),1.5,0))+IF((C42=2),2,0))+IF((C42="2+"),2.5,0))+IF((C42=3),3,0))+IF((C42="3+"),3.5,0) -> 0 | T42: =Interview!$B$102 -> Implementation | U42: =Interview!$B$131 -> Defect Management | V42: 0 | W42: 0 | X42: =C42 -> 0 | Y42: 0 | Z42: 0
A43: =Interview!$B$145 -> Verification | B43: =Interview!$B$146 -> Architecture Assessment | C43: =Roadmap!M102 -> 0 | D43: =Roadmap!L102 -> 0 | E43: =Roadmap!L103 -> 0 | F43: =Roadmap!L104 -> 0 | G43: =(((((IF((C43="0+"),0.5,0)+IF((C43=1),1,0))+IF((C43="1+"),1.5,0))+IF((C43=2),2,0))+IF((C43="2+"),2.5,0))+IF((C43=3),3,0))+IF((C43="3+"),3.5,0) -> 0 | T43: =Interview!$B$145 -> Verification | U43: =Interview!$B$146 -> Architecture Assessment | V43: 0 | W43: 0 | X43: 0 | Y43: =C43 -> 0 | Z43: 0
A44: =Interview!$B$145 -> Verification | B44: =Interview!$B$160 -> Requirements Testing | C44: =Roadmap!M111 -> 0 | D44: =Roadmap!L111 -> 0 | E44: =Roadmap!L112 -> 0 | F44: =Roadmap!L113 -> 0 | G44: =(((((IF((C44="0+"),0.5,0)+IF((C44=1),1,0))+IF((C44="1+"),1.5,0))+IF((C44=2),2,0))+IF((C44="2+"),2.5,0))+IF((C44=3),3,0))+IF((C44="3+"),3.5,0) -> 0 | T44: =Interview!$B$145 -> Verification | U44: =Interview!$B$160 -> Requirements Testing | V44: 0 | W44: 0 | X44: 0 | Y44: =C44 -> 0 | Z44: 0
A45: =Interview!$B$145 -> Verification | B45: =Interview!$B$174 -> Security Testing | C45: =Roadmap!M120 -> 0 | D45: =Roadmap!L120 -> 0 | E45: =Roadmap!L121 -> 0 | F45: =Roadmap!L122 -> 0 | G45: =(((((IF((C45="0+"),0.5,0)+IF((C45=1),1,0))+IF((C45="1+"),1.5,0))+IF((C45=2),2,0))+IF((C45="2+"),2.5,0))+IF((C45=3),3,0))+IF((C45="3+"),3.5,0) -> 0 | T45: =Interview!$B$145 -> Verification | U45: =Interview!$B$174 -> Security Testing | V45: 0 | W45: 0 | X45: 0 | Y45: =C45 -> 0 | Z45: 0
...

Sheet Roadmap
B1: =CONCATENATE("SAMM Assessment Interview: ",D11," For ",D10) -> SAMM Assessment Interview: For
B3: Instructions
B4: Interview an individual based on the questions below organized according to SAMM Business Functions and Security Practices.
B5: Select the best answer from the multiple choice drop down selections in the answer column.
B6: Document additional information such as how and why in the "Interview Notes" column.
B7: The formulas in hidden columns F-H will calculate the scores and update the Rating boxes and other worksheets as needed.
B8: Once the interview is complete, go to the "Scorecard" sheet and follow instructions.
B10: Organization: | D10: =IF(ISBLANK(Interview!D10),"",Interview!D10)
B11: Team/Application: | D11: =IF(ISBLANK(Interview!D11),"",Interview!D11)
B12: Interview Date: | D12: =IF(ISBLANK(Interview!D12),"",Interview!D12)
B13: Team Lead: | D13: =IF(ISBLANK(Interview!D13),"",Interview!D13)
A14: =IF(A15=A16,"OK","Problem") -> OK | B14: Contributors: | D14: =IF(ISBLANK(Interview!D14),"",Interview!D14)
A15: =COUNTA('imp-questions'!A2:A300) -> 90
A16: =COUNTA(A18:A175) -> 90 | B16: Governance | F16: Current | J16: Phase 1 | N16: Phase 2 | R16: Phase 3 | V16: Phase 4
B17: Stream | C17: Level | D17: Strategy & Metrics | F17: Answer | I17: Rating | J17: Answer | M17: Rating | N17: Answer | Q17: Rating | R17: Answer | U17: Rating | V17: Answer | Y17: Rating | Z17: Gap vs Current
A18: =Interview!A18 -> G-SM-A-1-1 | B18: =INDEX('imp-questions'!D:D, MATCH(A18, 'imp-questions'!A:A, 0)) -> Create and Promote | C18: =INDEX('imp-questions'!E:E, MATCH(A18, 'imp-questions'!A:A, 0)) -> 1 | D18: =INDEX('imp-questions'!F:F, MATCH(A18, 'imp-questions'!A:A, 0)) -> Do you understand the enterprise-wide risk appetite for your applications? | E18: =CHAR(65+INDEX('imp-questions'!H:H, MATCH(A18, 'imp-questions'!A:A, 0))) -> N | F18: =IF(ISBLANK(Interview!F18),"",Interview!F18) | G18: =IFERROR(INDEX(INDIRECT("Ans" & E18 & "TBL"), MATCH(F18, INDEX(INDIRECT("Ans" & E18 & "TBL"), 0, 1), 0), 2), 0) -> 0 | H18: =IFERROR(AVERAGE(G18,G22),0) -> 0 | I18: =SUM(H18,H19,H20) -> 0 | J18: =F18 | K18: =IFERROR(INDEX(INDIRECT("Ans" & E18 & "TBL"), MATCH(J18, INDEX(INDIRECT("Ans" & E18 & "TBL"), 0, 1), 0), 2), 0) -> 0 | L18: =IFERROR(AVERAGE(K18,K22),0) -> 0 | M18: =SUM(L18,L19,L20) -> 0 | N18: =J18 | O18: =IFERROR(INDEX(INDIRECT("Ans" & E18 & "TBL"), MATCH(N18, INDEX(INDIRECT("Ans" & E18 & "TBL"), 0, 1), 0), 2), 0) -> 0 | P18: =IFERROR(AVERAGE(O18,O22),0) -> 0 | Q18: =SUM(P18,P19,P20) -> 0 | R18: =N18 | S18: =IFERROR(INDEX(INDIRECT("Ans" & E18 & "TBL"), MATCH(R18, INDEX(INDIRECT("Ans" & E18 & "TBL"), 0, 1), 0), 2), 0) -> 0 | T18: =IFERROR(AVERAGE(S18,S22),0) -> 0 | U18: =SUM(T18,T19,T20) -> 0 | V18: =R18 | W18: =IFERROR(INDEX(INDIRECT("Ans" & E18 & "TBL"), MATCH(V18, INDEX(INDIRECT("Ans" & E18 & "TBL"), 0, 1), 0), 2), 0) -> 0 | X18: =IFERROR(AVERAGE(W18,W22),0) -> 0 | Y18: =SUM(X18,X19,X20) -> 0 | Z18: =IFERROR(Y18-I18,Y18-LEFT(I18,1)) -> 0
A19: =Interview!A20 -> G-SM-A-2-1 | C19: =INDEX('imp-questions'!E:E, MATCH(A19, 'imp-questions'!A:A, 0)) -> 2 | D19: =INDEX('imp-questions'!F:F, MATCH(A19, 'imp-questions'!A:A, 0)) -> Do you have a strategic plan for application security and use it to make decisions? | E19: =CHAR(65+INDEX('imp-questions'!H:H, MATCH(A19, 'imp-questions'!A:A, 0))) -> O | F19: =IF(ISBLANK(Interview!F20),"",Interview!F20) | G19: =IFERROR(INDEX(INDIRECT("Ans" & E19 & "TBL"), MATCH(F19, INDEX(INDIRECT("Ans" & E19 & "TBL"), 0, 1), 0), 2), 0) -> 0 | H19: =IFERROR(AVERAGE(G19,G23),0) -> 0 | J19: =F19 | K19: =IFERROR(INDEX(INDIRECT("Ans" & E19 & "TBL"), MATCH(J19, INDEX(INDIRECT("Ans" & E19 & "TBL"), 0, 1), 0), 2), 0) -> 0 | L19: =IFERROR(AVERAGE(K19,K23),0) -> 0 | N19: =J19 | O19: =IFERROR(INDEX(INDIRECT("Ans" & E19 & "TBL"), MATCH(N19, INDEX(INDIRECT("Ans" & E19 & "TBL"), 0, 1), 0), 2), 0) -> 0 | P19: =IFERROR(AVERAGE(O19,O23),0) -> 0 | R19: =N19 | S19: =IFERROR(INDEX(INDIRECT("Ans" & E19 & "TBL"), MATCH(R19, INDEX(INDIRECT("Ans" & E19 & "TBL"), 0, 1), 0), 2), 0) -> 0 | T19: =IFERROR(AVERAGE(S19,S23),0) -> 0 | V19: =R19 | W19: =IFERROR(INDEX(INDIRECT("Ans" & E19 & "TBL"), MATCH(V19, INDEX(INDIRECT("Ans" & E19 & "TBL"), 0, 1), 0), 2), 0) -> 0 | X19: =IFERROR(AVERAGE(W19,W23),0) -> 0
A20: =Interview!A22 -> G-SM-A-3-1 | C20: =INDEX('imp-questions'!E:E, MATCH(A20, 'imp-questions'!A:A, 0)) -> 3 | D20: =INDEX('imp-questions'!F:F, MATCH(A20, 'imp-questions'!A:A, 0)) -> Do you regularly review and update the Strategic Plan for Application Security? | E20: =CHAR(65+INDEX('imp-questions'!H:H, MATCH(A20, 'imp-questions'!A:A, 0))) -> P | F20: =IF(ISBLANK(Interview!F22),"",Interview!F22) | G20: =IFERROR(INDEX(INDIRECT("Ans" & E20 & "TBL"), MATCH(F20, INDEX(INDIRECT("Ans" & E20 & "TBL"), 0, 1), 0), 2), 0) -> 0 | H20: =IFERROR(AVERAGE(G20,G24),0) -> 0 | J20: =F20 | K20: =IFERROR(INDEX(INDIRECT("Ans" & E20 & "TBL"), MATCH(J20, INDEX(INDIRECT("Ans" & E20 & "TBL"), 0, 1), 0), 2), 0) -> 0 | L20: =IFERROR(AVERAGE(K20,K24),0) -> 0 | N20: =J20 | O20: =IFERROR(INDEX(INDIRECT("Ans" & E20 & "TBL"), MATCH(N20, INDEX(INDIRECT("Ans" & E20 & "TBL"), 0, 1), 0), 2), 0) -> 0 | P20: =IFERROR(AVERAGE(O20,O24),0) -> 0 | R20: =N20 | S20: =IFERROR(INDEX(INDIRECT("Ans" & E20 & "TBL"), MATCH(R20, INDEX(INDIRECT("Ans" & E20 & "TBL"), 0, 1), 0), 2), 0) -> 0 | T20: =IFERROR(AVERAGE(S20,S24),0) -> 0 | V20: =R20 | W20: =IFERROR(INDEX(INDIRECT("Ans" & E20 & "TBL"), MATCH(V20, INDEX(INDIRECT("Ans" & E20 & "TBL"), 0, 1), 0), 2), 0) -> 0 | X20: =IFERROR(AVERAGE(W20,W24),0) -> 0
A22: =Interview!A25 -> G-SM-B-1-1 | B22: =INDEX('imp-questions'!D:D, MATCH(A22, 'imp-questions'!A:A, 0)) -> Measure and Improve | C22: =INDEX('imp-questions'!E:E, MATCH(A22, 'imp-questions'!A:A, 0)) -> 1 | D22: =INDEX('imp-questions'!F:F, MATCH(A22, 'imp-questions'!A:A, 0)) -> Do you use a set of metrics to measure the effectiveness and efficiency of the application security program across applications? | E22: =CHAR(65+INDEX('imp-questions'!H:H, MATCH(A22, 'imp-questions'!A:A, 0))) -> Q | F22: =IF(ISBLANK(Interview!F25),"",Interview!F25) | G22: =IFERROR(INDEX(INDIRECT("Ans" & E22 & "TBL"), MATCH(F22, INDEX(INDIRECT("Ans" & E22 & "TBL"), 0, 1), 0), 2), 0) -> 0 | J22: =F22 | K22: =IFERROR(INDEX(INDIRECT("Ans" & E22 & "TBL"), MATCH(J22, INDEX(INDIRECT("Ans" & E22 & "TBL"), 0, 1), 0), 2), 0) -> 0 | N22: =J22 | O22: =IFERROR(INDEX(INDIRECT("Ans" & E22 & "TBL"), MATCH(N22, INDEX(INDIRECT("Ans" & E22 & "TBL"), 0, 1), 0), 2), 0) -> 0 | R22: =N22 | S22: =IFERROR(INDEX(INDIRECT("Ans" & E22 & "TBL"), MATCH(R22, INDEX(INDIRECT("Ans" & E22 & "TBL"), 0, 1), 0), 2), 0) -> 0 | V22: =R22 | W22: =IFERROR(INDEX(INDIRECT("Ans" & E22 & "TBL"), MATCH(V22, INDEX(INDIRECT("Ans" & E22 & "TBL"), 0, 1), 0), 2), 0) -> 0
A23: =Interview!A27 -> G-SM-B-2-1 | C23: =INDEX('imp-questions'!E:E, MATCH(A23, 'imp-questions'!A:A, 0)) -> 2 | D23: =INDEX('imp-questions'!F:F, MATCH(A23, 'imp-questions'!A:A, 0)) -> Did you define Key Performance Indicators (KPI) from available application security metrics? | E23: =CHAR(65+INDEX('imp-questions'!H:H, MATCH(A23, 'imp-questions'!A:A, 0))) -> S | F23: =IF(ISBLANK(Interview!F27),"",Interview!F27) | G23: =IFERROR(INDEX(INDIRECT("Ans" & E23 & "TBL"), MATCH(F23, INDEX(INDIRECT("Ans" & E23 & "TBL"), 0, 1), 0), 2), 0) -> 0 | J23: =F23 | K23: =IFERROR(INDEX(INDIRECT("Ans" & E23 & "TBL"), MATCH(J23, INDEX(INDIRECT("Ans" & E23 & "TBL"), 0, 1), 0), 2), 0) -> 0 | N23: =J23 | O23: =IFERROR(INDEX(INDIRECT("Ans" & E23 & "TBL"), MATCH(N23, INDEX(INDIRECT("Ans" & E23 & "TBL"), 0, 1), 0), 2), 0) -> 0 | R23: =N23 | S23: =IFERROR(INDEX(INDIRECT("Ans" & E23 & "TBL"), MATCH(R23, INDEX(INDIRECT("Ans" & E23 & "TBL"), 0, 1), 0), 2), 0) -> 0 | V23: =R23 | W23: =IFERROR(INDEX(INDIRECT("Ans" & E23 & "TBL"), MATCH(V23, INDEX(INDIRECT("Ans" & E23 & "TBL"), 0, 1), 0), 2), 0) -> 0
A24: =Interview!A29 -> G-SM-B-3-1 | C24: =INDEX('imp-questions'!E:E, MATCH(A24, 'imp-questions'!A:A, 0)) -> 3 | D24: =INDEX('imp-questions'!F:F, MATCH(A24, 'imp-questions'!A:A, 0)) -> Do you update the Application Security strategy and roadmap based on application security metrics and KPIs? | E24: =CHAR(65+INDEX('imp-questions'!H:H, MATCH(A24, 'imp-questions'!A:A, 0))) -> P | F24: =IF(ISBLANK(Interview!F29),"",Interview!F29) | G24: =IFERROR(INDEX(INDIRECT("Ans" & E24 & "TBL"), MATCH(F24, INDEX(INDIRECT("Ans" & E24 & "TBL"), 0, 1), 0), 2), 0) -> 0 | J24: =F24 | K24: =IFERROR(INDEX(INDIRECT("Ans" & E24 & "TBL"), MATCH(J24, INDEX(INDIRECT("Ans" & E24 & "TBL"), 0, 1), 0), 2), 0) -> 0 | N24: =J24 | O24: =IFERROR(INDEX(INDIRECT("Ans" & E24 & "TBL"), MATCH(N24, INDEX(INDIRECT("Ans" & E24 & "TBL"), 0, 1), 0), 2), 0) -> 0 | R24: =N24 | S24: =IFERROR(INDEX(INDIRECT("Ans" & E24 & "TBL"), MATCH(R24, INDEX(INDIRECT("Ans" & E24 & "TBL"), 0, 1), 0), 2), 0) -> 0 | V24: =R24 | W24: =IFERROR(INDEX(INDIRECT("Ans" & E24 & "TBL"), MATCH(V24, INDEX(INDIRECT("Ans" & E24 & "TBL"), 0, 1), 0), 2), 0) -> 0
B26: Stream | C26: Level | D26: Policy & Compliance | F26: Answer | I26: Rating | J26: Answer | M26: Rating | N26: Answer | Q26: Rating | R26: Answer | U26: Rating | V26: Answer | Y26: Rating | Z26: Gap vs Current
A27: =Interview!A32 -> G-PC-A-1-1 | B27: =INDEX('imp-questions'!D:D, MATCH(A27, 'imp-questions'!A:A, 0)) -> Policy and Standards | C27: =INDEX('imp-questions'!E:E, MATCH(A27, 'imp-questions'!A:A, 0)) -> 1 | D27: =INDEX('imp-questions'!F:F, MATCH(A27, 'imp-questions'!A:A, 0)) -> Do you have and apply a common set of policies and standards throughout your organization? | E27: =CHAR(65+INDEX('imp-questions'!H:H, MATCH(A27, 'imp-questions'!A:A, 0))) -> A | F27: =IF(ISBLANK(Interview!F32),"",Interview!F32) | G27: =IFERROR(INDEX(INDIRECT("Ans" & E27 & "TBL"), MATCH(F27, INDEX(INDIRECT("Ans" & E27 & "TBL"), 0, 1), 0), 2), 0) -> 0 | H27: =IFERROR(AVERAGE(G27,G31),0) -> 0 | I27: =SUM(H27,H28,H29) -> 0 | J27: =F27 | K27: =IFERROR(INDEX(INDIRECT("Ans" & E27 & "TBL"), MATCH(J27, INDEX(INDIRECT("Ans" & E27 & "TBL"), 0, 1), 0), 2), 0) -> 0 | L27: =IFERROR(AVERAGE(K27,K31),0) -> 0 | M27: =SUM(L27,L28,L29) -> 0 | N27: =J27 | O27: =IFERROR(INDEX(INDIRECT("Ans" & E27 & "TBL"), MATCH(N27, INDEX(INDIRECT("Ans" & E27 & "TBL"), 0, 1), 0), 2), 0) -> 0 | P27: =IFERROR(AVERAGE(O27,O31),0) -> 0 | Q27: =SUM(P27,P28,P29) -> 0 | R27: =N27 | S27: =IFERROR(INDEX(INDIRECT("Ans" & E27 & "TBL"), MATCH(R27, INDEX(INDIRECT("Ans" & E27 & "TBL"), 0, 1), 0), 2), 0) -> 0 | T27: =IFERROR(AVERAGE(S27,S31),0) -> 0 | U27: =SUM(T27,T28,T29) -> 0 | V27: =R27 | W27: =IFERROR(INDEX(INDIRECT("Ans" & E27 & "TBL"), MATCH(V27, INDEX(INDIRECT("Ans" & E27 & "TBL"), 0, 1), 0), 2), 0) -> 0 | X27: =IFERROR(AVERAGE(W27,W31),0) -> 0 | Y27: =SUM(X27,X28,X29) -> 0 | Z27: =IFERROR(Y27-I27,Y27-LEFT(I27,1)) -> 0
A28: =Interview!A34 -> G-PC-A-2-1 | C28: =INDEX('imp-questions'!E:E, MATCH(A28, 'imp-questions'!A:A, 0)) -> 2 | D28: =INDEX('imp-questions'!F:F, MATCH(A28, 'imp-questions'!A:A, 0)) -> Do you publish the organization's policies as test scripts or run-books for easy interpretation by development teams? | E28: =CHAR(65+INDEX('imp-questions'!H:H, MATCH(A28, 'imp-questions'!A:A, 0))) -> C | F28: =IF(ISBLANK(Interview!F34),"",Interview!F34) | G28: =IFERROR(INDEX(INDIRECT("Ans" & E28 & "TBL"), MATCH(F28, INDEX(INDIRECT("Ans" & E28 & "TBL"), 0, 1), 0), 2), 0) -> 0 | H28: =IFERROR(AVERAGE(G28,G32),0) -> 0 | J28: =F28 | K28: =IFERROR(INDEX(INDIRECT("Ans" & E28 & "TBL"), MATCH(J28, INDEX(INDIRECT("Ans" & E28 & "TBL"), 0, 1), 0), 2), 0) -> 0 | L28: =IFERROR(AVERAGE(K28,K32),0) -> 0 | N28: =J28 | O28: =IFERROR(INDEX(INDIRECT("Ans" & E28 & "TBL"), MATCH(N28, INDEX(INDIRECT("Ans" & E28 & "TBL"), 0, 1), 0), 2), 0) -> 0 | P28: =IFERROR(AVERAGE(O28,O32),0) -> 0 | R28: =N28 | S28: =IFERROR(INDEX(INDIRECT("Ans" & E28 & "TBL"), MATCH(R28, INDEX(INDIRECT("Ans" & E28 & "TBL"), 0, 1), 0), 2), 0) -> 0 | T28: =IFERROR(AVERAGE(S28,S32),0) -> 0 | V28: =R28 | W28: =IFERROR(INDEX(INDIRECT("Ans" & E28 & "TBL"), MATCH(V28, INDEX(INDIRECT("Ans" & E28 & "TBL"), 0, 1), 0), 2), 0) -> 0 | X28: =IFERROR(AVERAGE(W28,W32),0) -> 0
A29: =Interview!A36 -> G-PC-A-3-1 | C29: =INDEX('imp-questions'!E:E, MATCH(A29, 'imp-questions'!A:A, 0)) -> 3 | D29: =INDEX('imp-questions'!F:F, MATCH(A29, 'imp-questions'!A:A, 0)) -> Do you regularly report on policy and standard compliance, and use that information to guide compliance improvement efforts? | E29: =CHAR(65+INDEX('imp-questions'!H:H, MATCH(A29, 'imp-questions'!A:A, 0))) -> T | F29: =IF(ISBLANK(Interview!F36),"",Interview!F36) | G29: =IFERROR(INDEX(INDIRECT("Ans" & E29 & "TBL"), MATCH(F29, INDEX(INDIRECT("Ans" & E29 & "TBL"), 0, 1), 0), 2), 0) -> 0 | H29: =IFERROR(AVERAGE(G29,G33),0) -> 0 | J29: =F29 | K29: =IFERROR(INDEX(INDIRECT("Ans" & E29 & "TBL"), MATCH(J29, INDEX(INDIRECT("Ans" & E29 & "TBL"), 0, 1), 0), 2), 0) -> 0 | L29: =IFERROR(AVERAGE(K29,K33),0) -> 0 | N29: =J29 | O29: =IFERROR(INDEX(INDIRECT("Ans" & E29 & "TBL"), MATCH(N29, INDEX(INDIRECT("Ans" & E29 & "TBL"), 0, 1), 0), 2), 0) -> 0 | P29: =IFERROR(AVERAGE(O29,O33),0) -> 0 | R29: =N29 | S29: =IFERROR(INDEX(INDIRECT("Ans" & E29 & "TBL"), MATCH(R29, INDEX(INDIRECT("Ans" & E29 & "TBL"), 0, 1), 0), 2), 0) -> 0 | T29: =IFERROR(AVERAGE(S29,S33),0) -> 0 | V29: =R29 | W29: =IFERROR(INDEX(INDIRECT("Ans" & E29 & "TBL"), MATCH(V29, INDEX(INDIRECT("Ans" & E29 & "TBL"), 0, 1), 0), 2), 0) -> 0 | X29: =IFERROR(AVERAGE(W29,W33),0) -> 0
A31: =Interview!A39 -> G-PC-B-1-1 | B31: =INDEX('imp-questions'!D:D, MATCH(A31, 'imp-questions'!A:A, 0)) -> Compliance Management | C31: =INDEX('imp-questions'!E:E, MATCH(A31, 'imp-questions'!A:A, 0)) -> 1 | D31: =INDEX('imp-questions'!F:F, MATCH(A31, 'imp-questions'!A:A, 0)) -> Do you have a complete picture of your external compliance obligations? | E31: =CHAR(65+INDEX('imp-questions'!H:H, MATCH(A31, 'imp-questions'!A:A, 0))) -> A | F31: =IF(ISBLANK(Interview!F39),"",Interview!F39) | G31: =IFERROR(INDEX(INDIRECT("Ans" & E31 & "TBL"), MATCH(F31, INDEX(INDIRECT("Ans" & E31 & "TBL"), 0, 1), 0), 2), 0) -> 0 | J31: =F31 | K31: =IFERROR(INDEX(INDIRECT("Ans" & E31 & "TBL"), MATCH(J31, INDEX(INDIRECT("Ans" & E31 & "TBL"), 0, 1), 0), 2), 0) -> 0 | N31: =J31 | O31: =IFERROR(INDEX(INDIRECT("Ans" & E31 & "TBL"), MATCH(N31, INDEX(INDIRECT("Ans" & E31 & "TBL"), 0, 1), 0), 2), 0) -> 0 | R31: =N31 | S31: =IFERROR(INDEX(INDIRECT("Ans" & E31 & "TBL"), MATCH(R31, INDEX(INDIRECT("Ans" & E31 & "TBL"), 0, 1), 0), 2), 0) -> 0 | V31: =R31 | W31: =IFERROR(INDEX(INDIRECT("Ans" & E31 & "TBL"), MATCH(V31, INDEX(INDIRECT("Ans" & E31 & "TBL"), 0, 1), 0), 2), 0) -> 0
A32: =Interview!A41 -> G-PC-B-2-1 | C32: =INDEX('imp-questions'!E:E, MATCH(A32, 'imp-questions'!A:A, 0)) -> 2 | D32: =INDEX('imp-questions'!F:F, MATCH(A32, 'imp-questions'!A:A, 0)) -> Do you have a standard set of security requirements and verification procedures addressing the organization's external compliance obligations? | E32: =CHAR(65+INDEX('imp-questions'!H:H, MATCH(A32, 'imp-questions'!A:A, 0))) -> U | F32: =IF(ISBLANK(Interview!F41),"",Interview!F41) | G32: =IFERROR(INDEX(INDIRECT("Ans" & E32 & "TBL"), MATCH(F32, INDEX(INDIRECT("Ans" & E32 & "TBL"), 0, 1), 0), 2), 0) -> 0 | J32: =F32 | K32: =IFERROR(INDEX(INDIRECT("Ans" & E32 & "TBL"), MATCH(J32, INDEX(INDIRECT("Ans" & E32 & "TBL"), 0, 1), 0), 2), 0) -> 0 | N32: =J32 | O32: =IFERROR(INDEX(INDIRECT("Ans" & E32 & "TBL"), MATCH(N32, INDEX(INDIRECT("Ans" & E32 & "TBL"), 0, 1), 0), 2), 0) -> 0 | R32: =N32 | S32: =IFERROR(INDEX(INDIRECT("Ans" & E32 & "TBL"), MATCH(R32, INDEX(INDIRECT("Ans" & E32 & "TBL"), 0, 1), 0), 2), 0) -> 0 | V32: =R32 | W32: =IFERROR(INDEX(INDIRECT("Ans" & E32 & "TBL"), MATCH(V32, INDEX(INDIRECT("Ans" & E32 & "TBL"), 0, 1), 0), 2), 0) -> 0
A33: =Interview!A43 -> G-PC-B-3-1 | C33: =INDEX('imp-questions'!E:E, MATCH(A33, 'imp-questions'!A:A, 0)) -> 3 | D33: =INDEX('imp-questions'!F:F, MATCH(A33, 'imp-questions'!A:A, 0)) -> Do you regularly report on adherence to external compliance obligations and use that information to guide efforts to close compliance gaps? | E33: =CHAR(65+INDEX('imp-questions'!H:H, MATCH(A33, 'imp-questions'!A:A, 0))) -> T | F33: =IF(ISBLANK(Interview!F43),"",Interview!F43) | G33: =IFERROR(INDEX(INDIRECT("Ans" & E33 & "TBL"), MATCH(F33, INDEX(INDIRECT("Ans" & E33 & "TBL"), 0, 1), 0), 2), 0) -> 0 | J33: =F33 | K33: =IFERROR(INDEX(INDIRECT("Ans" & E33 & "TBL"), MATCH(J33, INDEX(INDIRECT("Ans" & E33 & "TBL"), 0, 1), 0), 2), 0) -> 0 | N33: =J33 | O33: =IFERROR(INDEX(INDIRECT("Ans" & E33 & "TBL"), MATCH(N33, INDEX(INDIRECT("Ans" & E33 & "TBL"), 0, 1), 0), 2), 0) -> 0 | R33: =N33 | S33: =IFERROR(INDEX(INDIRECT("Ans" & E33 & "TBL"), MATCH(R33, INDEX(INDIRECT("Ans" & E33 & "TBL"), 0, 1), 0), 2), 0) -> 0 | V33: =R33 | W33: =IFERROR(INDEX(INDIRECT("Ans" & E33 & "TBL"), MATCH(V33, INDEX(INDIRECT("Ans" & E33 & "TBL"), 0, 1), 0), 2), 0) -> 0
B35: Stream | C35: Level | D35: Education & Guidance | F35: Answer | I35: Rating | J35: Answer | M35: Rating | N35: Answer | Q35: Rating | R35: Answer | U35: Rating | V35: Answer | Y35: Rating | Z35: Gap vs Current
A36: =Interview!A46 -> G-EG-A-1-1 | B36: =INDEX('imp-questions'!D:D, MATCH(A36, 'imp-questions'!A:A, 0)) -> Training and Awareness | C36: =INDEX('imp-questions'!E:E, MATCH(A36, 'imp-questions'!A:A, 0)) -> 1 | D36: =INDEX('imp-questions'!F:F, MATCH(A36, 'imp-questions'!A:A, 0)) -> Do you require employees involved with application development to take SDLC training? | E36: =CHAR(65+INDEX('imp-questions'!H:H, MATCH(A36, 'imp-questions'!A:A, 0))) -> B | F36: =IF(ISBLANK(Interview!F46),"",Interview!F46) | G36: =IFERROR(INDEX(INDIRECT("Ans" & E36 & "TBL"), MATCH(F36, INDEX(INDIRECT("Ans" & E36 & "TBL"), 0, 1), 0), 2), 0) -> 0 | H36: =IFERROR(AVERAGE(G36,G40),0) -> 0 | I36: =SUM(H36,H37,H38) -> 0 | J36: =F36 | K36: =IFERROR(INDEX(INDIRECT("Ans" & E36 & "TBL"), MATCH(J36, INDEX(INDIRECT("Ans" & E36 & "TBL"), 0, 1), 0), 2), 0) -> 0 | L36: =IFERROR(AVERAGE(K36,K40),0) -> 0 | M36: =SUM(L36,L37,L38) -> 0 | N36: =J36 | O36: =IFERROR(INDEX(INDIRECT("Ans" & E36 & "TBL"), MATCH(N36, INDEX(INDIRECT("Ans" & E36 & "TBL"), 0, 1), 0), 2), 0) -> 0 | P36: =IFERROR(AVERAGE(O36,O40),0) -> 0 | Q36: =SUM(P36,P37,P38) -> 0 | R36: =N36 | S36: =IFERROR(INDEX(INDIRECT("Ans" & E36 & "TBL"), MATCH(R36, INDEX(INDIRECT("Ans" & E36 & "TBL"), 0, 1), 0), 2), 0) -> 0 | T36: =IFERROR(AVERAGE(S36,S40),0) -> 0 | U36: =SUM(T36,T37,T38) -> 0 | V36: =R36 | W36: =IFERROR(INDEX(INDIRECT("Ans" & E36 & "TBL"), MATCH(V36, INDEX(INDIRECT("Ans" & E36 & "TBL"), 0, 1), 0), 2), 0) -> 0 | X36: =IFERROR(AVERAGE(W36,W40),0) -> 0 | Y36: =SUM(X36,X37,X38) -> 0 | Z36: =IFERROR(Y36-I36,Y36-LEFT(I36,1)) -> 0
A37: =Interview!A48 -> G-EG-A-2-1 | C37: =INDEX('imp-questions'!E:E, MATCH(A37, 'imp-questions'!A:A, 0)) -> 2 | D37: =INDEX('imp-questions'!F:F, MATCH(A37, 'imp-questions'!A:A, 0)) -> Is training customized for individual roles such as developers, testers, or security champions? | E37: =CHAR(65+INDEX('imp-questions'!H:H, MATCH(A37, 'imp-questions'!A:A, 0))) -> D | F37: =IF(ISBLANK(Interview!F48),"",Interview!F48) | G37: =IFERROR(INDEX(INDIRECT("Ans" & E37 & "TBL"), MATCH(F37, INDEX(INDIRECT("Ans" & E37 & "TBL"), 0, 1), 0), 2), 0) -> 0 | H37: =IFERROR(AVERAGE(G37,G41),0) -> 0 | J37: =F37 | K37: =IFERROR(INDEX(INDIRECT("Ans" & E37 & "TBL"), MATCH(J37, INDEX(INDIRECT("Ans" & E37 & "TBL"), 0, 1), 0), 2), 0) -> 0 | L37: =IFERROR(AVERAGE(K37,K41),0) -> 0 | N37: =J37 | O37: =IFERROR(INDEX(INDIRECT("Ans" & E37 & "TBL"), MATCH(N37, INDEX(INDIRECT("Ans" & E37 & "TBL"), 0, 1), 0), 2), 0) -> 0 | P37: =IFERROR(AVERAGE(O37,O41),0) -> 0 | R37: =N37 | S37: =IFERROR(INDEX(INDIRECT("Ans" & E37 & "TBL"), MATCH(R37, INDEX(INDIRECT("Ans" & E37 & "TBL"), 0, 1), 0), 2), 0) -> 0 | T37: =IFERROR(AVERAGE(S37,S41),0) -> 0 | V37: =R37 | W37: =IFERROR(INDEX(INDIRECT("Ans" & E37 & "TBL"), MATCH(V37, INDEX(INDIRECT("Ans" & E37 & "TBL"), 0, 1), 0), 2), 0) -> 0 | X37: =IFERROR(AVERAGE(W37,W41),0) -> 0
A38: =Interview!A50 -> G-EG-A-3-1 | C38: =INDEX('imp-questions'!E:E, MATCH(A38, 'imp-questions'!A:A, 0)) -> 3 | D38: =INDEX('imp-questions'!F:F, MATCH(A38, 'imp-questions'!A:A, 0)) -> Have you implemented a Learning Management System or equivalent to track employee training and certification processes? | E38: =CHAR(65+INDEX('imp-questions'!H:H, MATCH(A38, 'imp-questions'!A:A, 0))) -> D | F38: =IF(ISBLANK(Interview!F50),"",Interview!F50) | G38: =IFERROR(INDEX(INDIRECT("Ans" & E38 & "TBL"), MATCH(F38, INDEX(INDIRECT("Ans" & E38 & "TBL"), 0, 1), 0), 2), 0) -> 0 | H38: =IFERROR(AVERAGE(G38,G42),0) -> 0 | J38: =F38 | K38: =IFERROR(INDEX(INDIRECT("Ans" & E38 & "TBL"), MATCH(J38, INDEX(INDIRECT("Ans" & E38 & "TBL"), 0, 1), 0), 2), 0) -> 0 | L38: =IFERROR(AVERAGE(K38,K42),0) -> 0 | N38: =J38 | O38: =IFERROR(INDEX(INDIRECT("Ans" & E38 & "TBL"), MATCH(N38, INDEX(INDIRECT("Ans" & E38 & "TBL"), 0, 1), 0), 2), 0) -> 0 | P38: =IFERROR(AVERAGE(O38,O42),0) -> 0 | R38: =N38 | S38: =IFERROR(INDEX(INDIRECT("Ans" & E38 & "TBL"), MATCH(R38, INDEX(INDIRECT("Ans" & E38 & "TBL"), 0, 1), 0), 2), 0) -> 0 | T38: =IFERROR(AVERAGE(S38,S42),0) -> 0 | V38: =R38 | W38: =IFERROR(INDEX(INDIRECT("Ans" & E38 & "TBL"), MATCH(V38, INDEX(INDIRECT("Ans" & E38 & "TBL"), 0, 1), 0), 2), 0) -> 0 | X38: =IFERROR(AVERAGE(W38,W42),0) -> 0
